Workbook
Name Z_16822E29_7107_44E0_879B_999A9E1047E8_.wvu.PrintArea: 'Aluminium Foil'!$A$1:$I$97
Name Z_16822E29_7107_44E0_879B_999A9E1047E8_.wvu.PrintArea: Bagasse!$A$1:$H$97

Sheet Summary Sheet
A1: Neeyog Packaging
A2: OFF: 20, Gr Floor,Sidhpura Ind.Estate,S.V.Road,Gaiwadi Rd,Near Agilus Diagnostic Center,Goregaon(W),Mum- 062
A3: Phone : 022-28760709 Mobile 9867607003 Email:neeyog@gmail.com
A4: www.neeyog.com/www.neeeyog.net/www.indiamart.com/neeyogpackaging/www.facebook.com/neeyogpack
A7: PRODUCTS SUMMARY LIST | C7: Date 16.06.2026
A8: SR No | B8: Description of the Products
A9: 1 | B9: ALUMINIUM FOIL ROLL & CONTAINERS | C9: 1-2
A10: =A9+1 -> 2 | B10: BIODEGRADABLE BAGASSE PRODUCTS | C10: 3-6
A11: =A10+1 -> 3 | B11: PAPER PRODUCTS (PLATE, BOWL, GLASS, BOXES & CONTAINER) | C11: 7-8
A12: =A11+1 -> 4 | B12: OLIVE REFERENCE | C12: 9-10
A13: =A12+1 -> 5 | B13: OLIVE PAPER PRODUCTS | C13: 11-15
A14: =A13+1 -> 6 | B14: PACKNSERVE | C14: 16-17
A15: =A14+1 -> 7 | B15: JP PRODUCTS | C15: 18-19
A16: =A15+1 -> 8 | B16: PS | C16: 20-23
A17: =A16+1 -> 9 | B17: PAPER BAGS SOS, CUTSHEETS | C17: 24
A18: =A17+1 -> 10 | B18: PAPER CARRY BAGS WITH IMAGES | C18: 25
A19: =A18+1 -> 11 | B19: PAPER CARRY BAGS | C19: 26
A20: =A19+1 -> 12 | B20: ARECALEAF BIODEGRADABLE PRODUCTS | C20: 27
A21: =A20+1 -> 13 | B21: TISSUE PAPER | C21: 28-29
... A43: =A42+1 -> 35 | B43: LAMINATED POUCHES | C43: 67-68
A48: Terms & Conditions
A49: 1. The Prices in this list are Ex Mumbai Freight charges will be Extra for outstation deliveries
A50: 2. The Gst charges will be charged as per price list mentioned
A51: 3. The above prices are subject to change
A52: 4. Payment within 30days incase of delay interest @18% P.a will be applicable Extra
A54: For Placing Orders
A55: Pranali/Ranjeet | B55: Mob no:- 8879559946
B56: Email:- orders@neeyog.com/neeyog@gmail.com
A58: For Sales Enquiry
A59: Madhuri | B59: Mob no:- 7045402654
A60: Pranali | B60: Mob no:-9867607005
B62: Email:- enquiry@neeyog.com/neeyog@gmail.com
A107: =A42+1 -> 35 | B107: PS MOUSSE CUPS | C107: 34-36
A108: =A107+1 -> 36 | B108: BIOPAC PRODUCTS | C108: 38

Sheet Aluminium Foil
A1: Neeyog Packaging | J1: summary sheet
A2: OFF: 20, Gr Floor,Sidhpura Ind.Estate,S.V.Road,Gaiwadi Rd,Near Agilus Diagnostic Center,Goregaon(W),Mum- 062 | T2: Mamtora | U2: MM
A3: Phone : 022-28760709 Mobile 9867607003 Email:neeyog@gmail.com | T3: Bhiwandi | U3: BW
A4: www.neeyog.com/www.neeyog.net/www.indiamart.com/neeyogpackaging/www.facebook.com/neeyogpack | P4: FM | R4: 1-2 DAY | T4: Shop | U4: SH
P5: LS | Q5: Limited Stock | R5: 3-4 DAYS | T5: Vapi | U5: VP
A6: Wholesale Aluminium Foil Wrap & Containers Price List | G6: ='Summary Sheet'!C7 -> Date 16.06.2026 | P6: APO | Q6: As per Order | R6: 15-20 DAYS | T6: Bansi | U6: BN
A7: Sr. No. | B7: Code | C7: HSN CODE | D7: Description (HSN Code 76071991) | E7: Rate Excl Gst | F7: Rate Incl Gst | G7: Per Pcs | H7: Std Pack | I7: GST Rate | J7: Primary Godown | K7: Movement | L7: Box Size | M7: Tally Name
D8: Hindalco Superwrap Foil
A9: 1 | B9: FR01SW | C9: 76071991 | D9: 9MTR Foil Wrap (SW) | E9: 55.5 | F9: =E9+E9*I9 -> 65.49 | G9: Pcs | H9: 50 | I9: 0.18 | J9: VP | K9: FM
A10: =A9+1 -> 2 | B10: FR02SW | C10: 76071991 | D10: 18MTR Foil Wrap (SW) 290mm | E10: 105.41 | F10: =E10+E10*I10 -> 124.3838 | G10: Pcs | H10: 50 | I10: 0.18 | J10: VP | K10: FM
A11: =A10+1 -> 3 | B11: FR01SW | C11: 76071991 | D11: 72MTR Foil Wrap (SW) 290mm | E11: 352.84 | F11: =E11+E11*I11 -> 416.3512 | G11: Pcs | H11: 25 | I11: 0.18 | J11: VP | K11: FM
A12: =A11+1 -> 4 | B12: FR02SW | C12: 76071991 | D12: 1KG Foil Wrap Box (NW) (SW) | E12: 525.08 | F12: =E12+E12*I12 -> 619.5944 | G12: Pcs | H12: 25 | I12: 0.18 | J12: VP | K12: FM
A14: 1 | B14: FR01FW | D14: 9MTR Foil Wrap (FW) | E14: 57.7 | F14: =E14+E14*I14 -> 68.086 | G14: Pcs | H14: 50 | I14: 0.18
A15: 2 | B15: FR02FW | D15: 18MTR Foil Wrap STD (FW) | E15: 108.6 | F15: =E15+E15*I15 -> 128.148 | G15: Pcs | H15: 50 | I15: 0.18
A16: 3 | B16: FR03FW | D16: 72MTR Foil Wrap (FW) | E16: 357.6 | F16: =E16+E16*I16 -> 421.968 | G16: Pcs | H16: 25 | I16: 0.18
A17: 4 | B17: FR04FW | D17: 1KG Foil Wrap Box (FW) | E17: 528.6 | F17: =E17+E17*I17 -> 623.748 | G17: Pcs | H17: 25 | I17: 0.18
D18: Minda Foil (HSN Code 76071991)
A19: 1 | C19: 76071991 | D19: 18MTR Foil Wrap (MI) | E19: 95.2 | F19: =E19+E19*I19 -> 112.336 | G19: Pcs | H19: 100 | I19: 0.18 | J19: VP | K19: FM
A20: =A19+1 -> 2 | C20: 76071991 | D20: 72 No(35 Mtr) Foil wrap | E20: 198 | F20: =E20+E20*I20 -> 233.64 | G20: Pcs | H20: 25 | I20: 0.18 | J20: - | K20: APO
A21: =A20+1 -> 3 | C21: 76071991 | D21: 72mtr Foil wrap | E21: 330 | F21: =E21+E21*I21 -> 389.4 | G21: Pcs | H21: 25 | I21: 0.18 | J21: - | K21: APO
A22: =A21+1 -> 4 | C22: 76071991 | D22: 1KG Foil Wrap (GW) (MI) | E22: 390.5 | F22: =E22+E22*I22 -> 460.79 | G22: Pcs | H22: 25 | I22: 0.18 | J22: BW | K22: FM
A23: =A22+1 -> 5 | C23: 76071991 | D23: 1kg Net 18mic | E23: 528 | F23: =E23+E23*I23 -> 623.04 | G23: Pcs | H23: 25 | I23: 0.18 | J23: - | K23: APO
D24: PNS Foil Wrap (HSN Code 76071991)
A25: 1 | D25: 18Mtr PNS Wrapp Fresh Foil Wrap * 100pcs | E25: 78 | F25: =E25+E25*I25 -> 92.04 | G25: Pcs | H25: 100 | I25: 0.18 | J25: VP | K25: FM
A26: 2 | D26: 72Mtr PNS Wrapp Fresh Foil Wrap * 25pcs | E26: 280 | F26: =E26+E26*I26 -> 330.4 | G26: Pcs | H26: 25 | I26: 0.18 | J26: VP | K26: FM
D27: WrappFresh Foil Wrap (HSN Code 76071991)
A28: 1 | C28: 76071991 | D28: Heavy Duty 14Mic WrappFresh Foil Wrap | E28: 199.15 | F28: =E28+E28*I28 -> 234.997 | G28: Pcs | H28: 25 | I28: 0.18 | J28: VP | K28: FM
A29: 2 | C29: 76071991 | D29: 18MTR Wrapp Fresh Foil Wrap (18Special) | E29: 53.4 | F29: =E29+E29*I29 -> 63.012 | G29: Pcs | H29: 50 | I29: 0.18 | J29: VP | K29: FM
B30: L x W x D | D30: Minda Foil Container (HSN Code 76151030) | E30: Rate Excl Gst | F30: Rate Incl Gst | G30: Per Pcs | H30: Std Pack | I30: GST Rate
A31: 1 | B31: 79X79X37 | C31: 76151030 | D31: 120ML Foil Cont (MI) | E31: 1.1 | F31: =E31+E31*I31 -> 1.155 | G31: Pcs | H31: 5000 | I31: 0.05 | J31: BW | K31: FM
A32: =A31+1 -> 2 | B32: 79X79X38 | C32: 76151030 | D32: 210ml Moments /Alu Fresh Foil Cont (Light) | E32: 1.4 | F32: =E32+E32*I32 -> 1.47 | G32: Pcs | H32: 2000 | I32: 0.05 | J32: BW | K32: APO
A33: 3 | B33: 79X79X38 | D33: 210ml Moments /Alu Fresh Foil Cont (Heavy) | E33: 1.84 | F33: =E33+E33*I33 -> 1.932 | G33: Pcs | H33: 2000 | I33: 0.05 | J33: BW | K33: APO
A34: =A33+1 -> 4 | B34: 130X103X43 | C34: 76151030 | D34: 250ML Foil Cont (MI) | E34: 1.44 | F34: =E34+E34*I34 -> 1.512 | G34: Pcs | H34: 2000 | I34: 0.05 | J34: BW | K34: FM
A35: 5 | B35: 142X117X45 | C35: 76151030 | D35: 450ML Foil Cont (MI) | E35: 1.92 | F35: =E35+E35*I35 -> 2.016 | G35: Pcs | H35: 1500 | I35: 0.05 | J35: BW | K35: FM
A36: =A35+1 -> 6 | B36: 187X131X48 | C36: 76151030 | D36: 600ML Foil Cont (MI) (Oval) | E36: 2.2 | F36: =E36+E36*I36 -> 2.31 | G36: Pcs | H36: 1000 | I36: 0.05 | J36: BW | K36: FM
A37: 7 | B37: 203X138X43 | C37: 76151030 | D37: 750ML Foil Cont (MI) | E37: 2.94 | F37: =E37+E37*I37 -> 3.087 | G37: Pcs | H37: 1000 | I37: 0.05 | J37: BW | K37: FM
A38: 8 | B38: 197X105X49 | C38: 76151030 | D38: 660ml Moments Foil Cont | E38: 2.94 | F38: =E38+E38*I38 -> 3.087 | G38: Pcs | H38: 1000 | I38: 0.05 | J38: BW | K38: APO
A39: 9 | B39: 277X177X38 | C39: 76151030 | D39: 3cp Minda Foil Cont | E39: 6 | F39: =E39+E39*I39 -> 6.3 | G39: Pcs | H39: 1200 | I39: 0.05 | J39: BW | K39: SM
A40: 10 | C40: 76151030 | D40: 4cp Minda Foil Cont (Heavy) | E40: 7.2 | F40: =E40+E40*I40 -> 7.56 | G40: Pcs | H40: 1200 | I40: 0.05 | J40: BW | K40: APO
A41: 11 | C41: 76151030 | D41: 4cp Minda Foil Cont (Light) | E41: 6 | F41: =E41+E41*I41 -> 6.3 | G41: Pcs | H41: 1200 | I41: 0.05 | J41: BW | K41: APO
...

Sheet Bagasse
A1: Neeyog Packaging | I1: summary sheet
A2: OFF: 20, Gr Floor,Sidhpura Ind.Estate,S.V.Road,Gaiwadi Rd,Near Agilus Diagnostic Center,Goregaon(W),Mum- 062 | P2: Mamtora | Q2: MM
A3: Phone : 022-28760709 Mobile 9867607003 Email:neeyog@gmail.com | P3: Bhiwandi | Q3: BW
A4: www.neeyog.com/www.indiamart.com/neeyogpackaging/www.facebook.com/neeyogpack | L4: FM | N4: 1-2 DAY | P4: Shop | Q4: SH
L5: LS | M5: Limited Stock | N5: 3-4 DAYS | P5: Vapi | Q5: VP
A6: Wholesale Bagasse Products Price List | F6: ='Summary Sheet'!C7 -> Date 16.06.2026 | L6: APO | M6: As per Order | N6: 15-20 DAYS | P6: Bansi | Q6: BN
A7: SR No | B7: Product Photos | C7: Description | D7: Excl. Gst Rate | E7: Incl. Gst Rate | F7: Unit | G7: Std Pack | H7: GST | I7: Primary Godown | J7: Movement
C8: B W Bagasse Products (Biodegradable)( HSN Code 48237010)
A9: 1 | C9: BW 6" RD PLATE BAGASSE | D9: 1.3 | E9: =D9+D9*H9 -> 1.365 | F9: Pcs | G9: 3000 | H9: 0.05 | I9: VP | J9: FM
A10: =A9+1 -> 2 | C10: BW 6" DEEP RD PLATE BAGASSE | D10: 1.4 | E10: =D10+D10*H10 -> 1.47 | F10: Pcs | G10: 2000 | H10: 0.05 | I10: VP | J10: APO
A11: =A10+1 -> 3 | C11: BW 7" RD PLATE BAGASSE | D11: 1.85 | E11: =D11+D11*H11 -> 1.9425 | F11: Pcs | G11: 2000 | H11: 0.05 | I11: VP | J11: FM
A12: =A11+1 -> 4 | C12: BW 9" PLAIN RD PLATE BAGASSE | D12: 2.95 | E12: =D12+D12*H12 -> 3.0975 | F12: Pcs | G12: 1000 | H12: 0.05 | J12: APO
A13: =A12+1 -> 5 | C13: BW 9" DEEP RD PLATE BAGASSE | D13: 3.25 | E13: =D13+D13*H13 -> 3.4125 | F13: Pcs | G13: 2000 | H13: 0.05 | I13: VP | J13: LS
A14: =A13+1 -> 6 | B14: New Arrival | C14: BW 3CP Mini Smart Plate Bagasse*1500Pcs | D14: 2.6 | E14: =D14+D14*H14 -> 2.73 | F14: Pcs | G14: 1500 | H14: 0.05 | I14: VP | J14: LS
A15: =A14+1 -> 7 | C15: BW 9" 3CP RD PLATE BAGASSE | D15: 3.25 | E15: =D15+D15*H15 -> 3.4125 | F15: Pcs | G15: 500 | H15: 0.05 | J15: APO
A16: =A15+1 -> 8 | C16: BW 9" 3CP SQ Plate Bagasse | D16: 4.1 | E16: =D16+D16*H16 -> 4.305 | F16: Pcs | G16: 500 | H16: 0.05 | J16: APO
A17: =A16+1 -> 9 | C17: BW 10" RD PLATE BAGASSE | D17: 3.6 | E17: =D17+D17*H17 -> 3.78 | F17: Pcs | G17: 1000 | H17: 0.05 | I17: VP | J17: FM
A18: =A17+1 -> 10 | C18: BW 10" 3CP RD Plate Bagasse | D18: 4.5 | E18: =D18+D18*H18 -> 4.725 | F18: Pcs | G18: 500 | H18: 0.05 | I18: VP | J18: LS
A19: =A18+1 -> 11 | C19: BW 10" 3CP SQ Plate Bagasse | D19: 5 | E19: =D19+D19*H19 -> 5.25 | F19: Pcs | G19: 700 | H19: 0.05 | I19: VP | J19: FM
A20: =A19+1 -> 12 | C20: BW 11" SUPER RD PLATE BAGASSE | D20: 4.2 | E20: =D20+D20*H20 -> 4.41 | F20: Pcs | G20: 750 | H20: 0.05 | I20: VP | J20: APO
A21: =A20+1 -> 13 | C21: BW 11" 4CP RD PLATE BAGASSE | D21: 4.2 | E21: =D21+D21*H21 -> 4.41 | F21: Pcs | G21: 500 | H21: 0.05 | I21: VP | J21: APO
A22: =A21+1 -> 14 | C22: BW 12" SUPER RD PLATE BAGASSE | D22: 5.7 | E22: =D22+D22*H22 -> 5.985 | F22: Pcs | G22: 500 | H22: 0.05 | I22: VP | J22: FM
A23: =A22+1 -> 15 | C23: BW 12" Plain Smart Plate | D23: 5.05 | E23: =D23+D23*H23 -> 5.3025 | F23: Pcs | G23: 2000 | H23: 0.05 | I23: VP | J23: APO
A24: =A23+1 -> 16 | C24: BW 12" 4CP SUPER RD PLATE BAGASSE | D24: 5.7 | E24: =D24+D24*H24 -> 5.985 | F24: Pcs | G24: 500 | H24: 0.05 | I24: VP | J24: FM
A25: =A24+1 -> 17 | C25: BW 4X4 SQ DONA ENJOY BAGASSE | D25: 1.1 | E25: =D25+D25*H25 -> 1.155 | F25: Pcs | G25: 3000 | H25: 0.05 | I25: VP | J25: FM
A26: =A25+1 -> 18 | C26: BW 7" SQR PLATE BAGASSE | D26: 1.95 | E26: =D26+D26*H26 -> 2.0475 | F26: Pcs | G26: 1000 | H26: 0.05 | I26: VP | J26: FM
A27: =A26+1 -> 19 | C27: BW 1D TRAY LITE SQ. BAGASSE | D27: 1.5 | E27: =D27+D27*H27 -> 1.575 | F27: Pcs | G27: 2000 | H27: 0.05 | I27: VP | J27: LS
A28: =A27+1 -> 20 | C28: BW 2D TRAY RECT BAGASSE | D28: 2.4 | E28: =D28+D28*H28 -> 2.52 | F28: Pcs | G28: 1000 | H28: 0.05 | I28: VP | J28: LS
A29: =A28+1 -> 21 | B29: New Arrival | C29: BW 2 Oz Bowl | D29: 1.05 | E29: =D29+D29*H29 -> 1.1025 | F29: Pcs | G29: 5000 | H29: 0.05 | J29: APO
A30: =A29+1 -> 22 | B30: New Arrival | C30: BW 4 Oz Bowl | D30: 1.06 | E30: =D30+D30*H30 -> 1.113 | F30: Pcs | G30: 5000 | H30: 0.05 | J30: APO
A31: =A30+1 -> 23 | C31: BW 6OZ 180ML BOWL BAGASSE | D31: 1.15 | E31: =D31+D31*H31 -> 1.2075 | F31: Pcs | G31: 3000 | H31: 0.05 | I31: VP | J31: LS
A32: =A31+1 -> 24 | C32: BW 7 Oz Bowl | D32: 1.35 | E32: =D32+D32*H32 -> 1.4175 | F32: Pcs | G32: 2000 | H32: 0.05 | J32: APO
A33: =A32+1 -> 25 | C33: BW 8OZ 240ML BOWL BAGASSE | D33: 1.6 | E33: =D33+D33*H33 -> 1.68 | F33: Pcs | G33: 2000 | H33: 0.05 | I33: VP | J33: LS
A34: =A33+1 -> 26 | C34: BW 12OZ 350ML BOWL BAGASSE | D34: 1.95 | E34: =D34+D34*H34 -> 2.0475 | F34: Pcs | G34: 1500 | H34: 0.05 | I34: VP | J34: LS
A35: =A34+1 -> 27 | C35: BW 16OZ 480ML BOWL BAGASSE | D35: 2.7 | E35: =D35+D35*H35 -> 2.835 | F35: Pcs | G35: 1200 | H35: 0.05 | I35: VP | J35: LS
A36: =A35+1 -> 28 | C36: BW024 500ml OVAL BOWL Baggase | D36: 3.7 | E36: =D36+D36*H36 -> 3.885 | F36: Pcs | G36: 1000 | H36: 0.05 | J36: APO
A37: =A36+1 -> 29 | C37: BW025 500ml OVAL LID Bagasse | D37: 2.7 | E37: =D37+D37*H37 -> 2.835 | F37: Pcs | G37: 1000 | H37: 0.05 | J37: APO
A38: =A37+1 -> 30 | C38: BW 750ml Rectangle Bowl | D38: 4.25 | E38: =D38+D38*H38 -> 4.4625 | F38: Pcs | G38: 1000 | H38: 0.05 | J38: APO
A39: =A38+1 -> 31 | C39: BW 750ml Rectangle Bowl Lid | D39: 2.7 | E39: =D39+D39*H39 -> 2.835 | F39: Pcs | G39: 1000 | H39: 0.05 | J39: APO
A40: =A39+1 -> 32 | C40: BW 6X6 CLAMSHELL BURGER BOX BAGASSE | D40: 4.78 | E40: =D40+D40*H40 -> 5.019 | F40: Pcs | G40: 700 | H40: 0.05 | I40: VP | J40: FM
...

Sheet Paper Products
A1: Neeyog Packaging | L1: summary sheet | V1: Vendor | W1: Brand | X1: Status | Y1: Key Products/Remarks
A2: OFF: 20, Gr Floor,Sidhpura Ind.Estate,S.V.Road,Gaiwadi Rd,Near Agilus Diagnostic Center,Goregaon(W), Mumbai-400062 | S2: Mamtora | T2: MM | V2: Shant Industries | W2: Eco Paper | X2: Primary | Y2: Economic Glass
A3: Phone : 022-28760709 Mobile 9867607003 Email:neeyog@gmail.com | S3: Bhiwandi | T3: BW | V3: Sahara Industry | W3: Clarro | X3: Primary | Y3: Leakproof, Plain Paper Cups
A4: www.neeyog.com/www.neeyog.net/www.indiamart.com/neeyogpackaging/www.facebook.com/neeyogpack | O4: FM | Q4: 1-2 DAY | S4: Shop | T4: SH | V4: Sai Swaram | W4: SI | X4: Primary | Y4: Ripple Cups / Double Wall (DW)
O5: LS | P5: Limited Stock | Q5: 3-4 DAYS | S5: Vapi | T5: VP
A6: Wholesale Paper Products Price List | I6: ='Summary Sheet'!C7 -> Date 16.06.2026 | O6: APO | P6: As per Order | Q6: 15-20 DAYS | S6: Bansi | T6: BN
A7: SR No | B7: Description | C7: GSM | D7: Diameter | G7: Basic | H7: Rate | I7: Per | J7: Carton | K7: GST | L7: Primary Godown | M7: Movement | N7: Old Description Name | V7: For customise print for more details at Printed Sheet
B8: ECO PAPER CUPS (TNPL) (HSN CODE 48236900) | C8: GSM | D8: Top | E8: BT | F8: H | G8: Rate | H8: Incl Gst | I8: Per | J8: Pack | K8: GST
A9: 1 | B9: 100ML Eco SI Paper Cup (67D) * 5000pcs | C9: 177 | D9: 67 | E9: 52 | F9: 52 | G9: 46 | H9: =G9+G9*18% -> 54.28 | I9: 100 | J9: 5000 | K9: 0.18 | L9: MM | M9: FM | N9: 100ML Eco SI Paper Cup | O9: =H9/1.09 -> 49.798165
A10: 2 | B10: 150ML Eco SI Paper Cup (69D) *5000pcs | C10: 177 | D10: 69 | E10: 52 | F10: 62 | G10: 50.5 | H10: =G10+G10*18% -> 59.59 | I10: 100 | J10: 5000 | K10: 0.18 | L10: MM | M10: FM | N10: 150ML Eco SI Paper Cup
A11: CLARRO PAPER CUPS TALL (Leak Proof) (HSN CODE 48236900) | C11: GSM | D11: Top | E11: BT | F11: H | G11: Rate | H11: Incl Gst | I11: Per | J11: Pack | K11: GST
A12: 1 | B12: 90ML SI Tall Paper Cup (Cllaro) (55D) | C12: 185 | D12: 55 | E12: 40 | F12: 60 | H12: =G12+G12*K12 -> 0 | I12: 100 | J12: 6000 | K12: 0.18 | L12: MM | M12: LS | N12: 90ML SI Tall Paper Cup (Cllaro) (55D)
A13: 2 | B13: 110ML SI Paper Cup Tall (Cllaro) (58D) * 6000pcs | C13: 185 | D13: 59 | E13: 39 | F13: 72 | G13: 54 | H13: =G13+G13*K13 -> 63.72 | I13: 100 | J13: 6000 | K13: 0.18 | L13: MM | M13: FM | N13: 110ML SI Tall Paper Cup (Cllaro) (58D)
B14: CLARRO PAPER CUPS (Leak Proof) (HSN CODE 48236900)
A15: 1 | B15: 100ML SI Paper Cup (Cllaro) (67D) * 5000pcs | C15: 185 | D15: 67 | E15: 52 | F15: 52 | G15: 52 | H15: =G15+G15*K15 -> 61.36 | I15: 100 | J15: 5000 | K15: 0.18 | L15: MM | M15: FM | N15: 100ML SI Paper Cup (Cllaro)
A16: =A15+1 -> 2 | B16: 100ML Paper Cups (Cllaro) | C16: 225 | D16: 67 | E16: 52 | F16: 52 | G16: 66.5 | H16: =G16+G16*K16 -> 78.47 | I16: 100 | J16: 5000 | K16: 0.18 | L16: MM | M16: FM | N16: 100ML Paper Cups (Cllaro)
A17: =A16+1 -> 3 | B17: 130ML SI Paper Cup (Cllaro) (68D) * 5000pcs | C17: 185 | D17: 68 | E17: 52 | F17: 58 | G17: 55 | H17: =G17+G17*K17 -> 64.9 | I17: 100 | J17: 5000 | K17: 0.18 | L17: MM | M17: FM | N17: 130ML SI Paper Cup (Cllaro)
A18: =A17+1 -> 4 | B18: 150ML SI Paper Cup (Cllaro) (69D) * 5000pcs | C18: 185 | D18: 69 | E18: 52 | F18: 62 | G18: 57 | H18: =G18+G18*K18 -> 67.26 | I18: 100 | J18: 5000 | K18: 0.18 | L18: MM | M18: FM | N18: 150ML SI Paper Cup (Cllaro)
A19: =A18+1 -> 5 | B19: 175ML SI Paper Cup (Cllaro) (71D) * 5000pcs | C19: 185 | D19: 71 | E19: 52 | F19: 71 | G19: 64.5 | H19: =G19+G19*K19 -> 76.11 | I19: 100 | J19: 5000 | K19: 0.18 | L19: MM | M19: FM | N19: 175ML SI Paper Cup (Cllaro)
A20: =A19+1 -> 6 | B20: 200ML SI Paper Cup (Cllaro) (72D) * 5000pcs | C20: 185 | D20: 72 | E20: 52 | F20: 75 | G20: 72 | H20: =G20+G20*K20 -> 84.96 | I20: 100 | J20: 5000 | K20: 0.18 | L20: MM | M20: FM | N20: 200ML SI Paper Cup (Cllaro)
A21: =A20+1 -> 7 | B21: 200ML SI Paper Cup (Cllaro) (72D) (225G) * 5000pcs | C21: 225 | D21: 72 | E21: 52 | F21: 75 | G21: 90 | H21: =G21+G21*K21 -> 106.2 | I21: 100 | J21: 5000 | K21: 0.18 | L21: MM | M21: FM | N21: 200ML SI Paper Cup (Cllaro)
A22: =A21+1 -> 8 | B22: 250ML SI Paper Cup (Cllaro) (77D) * 4000pcs | C22: 225 | D22: 77 | E22: 52 | F22: 97 | G22: 112 | H22: =G22+G22*K22 -> 132.16 | I22: 100 | J22: 4000 | K22: 0.18 | L22: MM | M22: FM | N22: 250ML SI Paper Cup (Cllaro)
A23: =A22+1 -> 9 | B23: 300ML SI Paper Cup (Cllaro) * 4000pcs | C23: 225 | D23: 80 | E23: 52 | F23: 109 | G23: 125 | H23: =G23+G23*K23 -> 147.5 | I23: 100 | J23: 4000 | K23: 0.18 | L23: MM | M23: FM | N23: 300ML SI Paper Cup (Cllaro)
A24: =A23+1 -> 10 | B24: 110ML Paper Cups Tall Printed | C24: 185 | D24: 67 | E24: 52 | F24: 52 | G24: 71 | H24: =G24+G24*K24 -> 83.78 | I24: 100 | J24: 6000 | K24: 0.18 | M24: APO | N24: 110ML Paper Cups Tall Printed
A25: =A24+1 -> 11 | B25: 150ML Paper Cups Printed | C25: 185 | D25: 69 | E25: 52 | F25: 62 | G25: 72 | H25: =G25+G25*K25 -> 84.96 | I25: 100 | J25: 5000 | K25: 0.18 | M25: APO | N25: 150ML Paper Cups Printed
A26: =A25+1 -> 12 | B26: 200MLPaper Cups PRINTED ( Cllaro) | C26: 195 | D26: 72 | E26: 52 | F26: 75 | G26: 90 | H26: =G26+G26*K26 -> 106.2 | I26: 100 | J26: 5000 | K26: 0.18 | M26: APO | N26: 200MLPaper Cups PRINTED ( Cllaro)
A27: 13 | B27: 240ML SI 8OZ Paper Cup (Cllaro) (280GSM) * 1000pcs | C27: 280 | D27: 80 | G27: 126 | H27: =G27+G27*K27 -> 148.68 | I27: 100 | J27: 1000 | K27: 0.18 | L27: MM | M27: FM | N27: 240ML SI 8OZ Paper Cup (Cllaro)
A28: Customisation Min Moq 50000 @20 Paise Extra Development Charges @ 4500/- Extra
B29: CLARRO PAPER WATI (HSN CODE 48236100) | C29: GSM | D29: Top | E29: BT | F29: H | G29: Rate | H29: Incl Gst | I29: Per | J29: Pack | K29: GST
A30: 1 | B30: 50ML SI Icecream Paper Wati (62D) | C30: 177 | D30: 63.75 | E30: 51.56 | F30: 36 | G30: 57 | H30: =G30+G30*K30 -> 67.26 | I30: 100Pcs | J30: 5000 | K30: 0.18 | L30: MM | M30: FM | N30: 50ML SI Icecream Paper Wati (62D)
A31: 2 | B31: 100ML SI Icecream Paper Wati (73D) | C31: 185 | D31: 74 | E31: 60.83 | F31: 41 | G31: 68.5 | H31: =G31+G31*K31 -> 80.83 | I31: 100Pcs | J31: 2500 | K31: 0.18 | L31: MM | M31: FM
A32: 3 | B32: 150ML SI Icecream Paper Wati | C32: 185 | D32: 76 | E32: 60.83 | F32: 52 | G32: 84.5 | H32: =G32+G32*K32 -> 99.71 | I32: 100Pcs | J32: 2500 | K32: 0.18 | L32: MM | M32: FM
B33: PAPER CUPS - Dolphin (HSN CODE 48236900) | D33: Top | E33: BT | F33: H | G33: Rate | H33: Incl Gst | I33: Unit | J33: Pack
A34: 1 | B34: 60ML DL Prnt Paper Cups | D34: 49 | E34: 36 | F34: 45 | G34: 28 | H34: =G34+G34*18% -> 33.04 | I34: 50 | J34: 9600 | K34: 0.18 | M34: APO | N34: New box pack is 10350
A35: 2 | B35: 80ML DL Tall Printed Paper Cups | D35: 52 | E35: 37 | F35: 50 | G35: 33 | H35: =G35+G35*18% -> 38.94 | I35: 50 | J35: 8800 | K35: 0.18
A36: 3 | B36: 90ML DL Paper Cups Plain | D36: 57 | E36: 42 | F36: 55 | G36: 39 | H36: =G36+G36*18% -> 46.02 | I36: 50 | J36: 6800 | K36: 0.18 | L36: MM | M36: FM
A37: 4 | B37: 150ML DL Paper Cups (68D) * 5000Pcs | D37: 68 | G37: 48.5 | H37: =G37+G37*18% -> 57.23 | I37: 50 | J37: 5500 | K37: 0.18
A38: 5 | B38: 200ML DL Paper Cups (72D) * 5000pc | D38: 72 | G38: 57.5 | H38: =G38+G38*18% -> 67.85 | I38: 50 | J38: 5000 | K38: 0.18
A39: PAGE 6
B40: Export Products (HSN - 4823) | C40: GSM | D40: Top l | E40: Top W | F40: H | G40: Rate | H40: Incl Gst | I40: Per | J40: Pack | K40: GST
...

Sheet Olive Reference 
A1: Neeyog Packaging | J1: Summary Sheet | P1: Mamtora | Q1: MM
A2: OFF:G20, Gr Floor,Sidhpura Ind.Estate,S.V.Road,Gaiwadi Rd,Near Agilus Diagnostic Center,Goregaon(W),Mum- 062 | P2: Bhiwandi | Q2: BW
A3: Phone : 022-28760709 Mobile 9867607003 Email:neeyog@gmail.com | L3: FM | N3: 1-2 DAY | P3: Shop | Q3: SH
A4: www.neeyog.com/www.neeyog.net/www.indiamart.com/neeyogpackaging/www.facebook.com/neeyogpack | L4: LS | M4: Limited Stock | N4: 3-4 DAYS | P4: Vapi | Q4: VP
L5: APO | M5: As per Order | N5: 15-20 DAYS | P5: Bansi | Q5: BN
A6: Wholesale Olive Paper Products Price List | G6: ='Summary Sheet'!C7 -> Date 16.06.2026
A8: SR No | B8: Code | C8: Description | E8: Top Dia | F8: Box Packing | G8: Basic Price / 100Pcs | H8: Incl GST /Pcs | I8: GST %
A9: Single Wall Plain Cups (HSN CODE 48236900)
A10: 1 | B10: 4001PL | C10: 100 ML PAPER CUP- Plain | E10: 62 | F10: 6000 | G10: 47.2 | H10: =G10+G10*I10 -> 55.696 | I10: 0.18
A11: 2 | B11: 4003PL | C11: 100 ML PAPER CUP- Plain | E11: 62 | F11: 6000 | G11: 48.5 | H11: =G11+G11*I11 -> 57.23 | I11: 0.18
A12: 3 | B12: 4006PL | C12: 4006PL 130ml S/W Paper Cup *6000pcs | E12: 65 | F12: 6000 | G12: 54.3 | H12: =G12+G12*I12 -> 64.074 | I12: 0.18
A13: =A12+1 -> 4 | B13: 4009PL | C13: 150 ML PAPER CUP - PLAIN | E13: 70 | F13: 5000 | G13: 53.1 | H13: =G13+G13*I13 -> 62.658 | I13: 0.18
A14: =A13+1 -> 5 | B14: 4013APL | C14: 4013APL 200ml S/W Paper Cup DLX Plain *4000pcs | E14: 73 | F14: 4000 | G14: 80 | H14: =G14+G14*I14 -> 94.4 | I14: 0.18
A15: =A14+1 -> 6 | B15: 4013PL | C15: 4013PL 200ml OE Paper Cup (73D) * 4000pc | E15: 73 | F15: 4000 | G15: 75.5 | H15: =G15+G15*I15 -> 89.09 | I15: 0.18
A16: =A15+1 -> 7 | B16: 4018PL | C16: 4018PL 250ml OE Paper Cup (80D) 205Gsm*2500Pcs | E16: 80 | F16: 2500 | G16: 86.15 | H16: =G16+G16*I16 -> 101.657 | I16: 0.18
A17: =A16+1 -> 8 | B17: 4022PL | C17: 300 ML PAPER CUP | E17: 80 | F17: 2500 | G17: 110 | H17: =G17+G17*I17 -> 129.8 | I17: 0.18
A18: 10 | B18: 4032 | C18: 4032 480ml OE S/W Paper Cup SB [Plain] * 1000pcs | F18: 1000
A19: Tall Paper Cups (HSN CODE 48236900)
A20: 1 | B20: 4008PL | C20: 4008PL 150ml S/W Tall Paper Cup Plain *5000pcs | E20: 66 | F20: 5000 | G20: 57.8 | H20: =G20+G20*I20 -> 68.204 | I20: 0.18
A21: 2 | B21: 4012PL | C21: 4012PL 200ML OE TALL PAPER CUP 2PE (69D) *4000Pcs | E21: 69 | F21: 4000 | G21: 70.8 | H21: =G21+G21*I21 -> 83.544 | I21: 0.18
A22: SINGLE WALL CUPS (2PE) (HSN CODE 48236900)
A23: 1 | B23: 4012 | C23: 200 ML TALL PAPER CUP | D23: 182 | E23: 69 | F23: 4000 | G23: 73.2 | H23: =G23+G23*I23 -> 86.376 | I23: 0.18
A24: =A23+1 -> 2 | B24: 4017A | C24: 250 ML PAPER CUP - DELUXE | E24: 73 | F24: 4000 | G24: 86.7 | H24: =G24+G24*I24 -> 102.306 | I24: 0.18
A25: =A24+1 -> 3 | B25: 4022 | C25: 300 ML PAPER CUP | D25: 202 | E25: 80 | F25: 2500 | G25: 1.15 | H25: =G25+G25*I25 -> 1.357 | I25: 0.18
A26: =A25+1 -> 4 | B26: 4026 | C26: 330 ML PAPER CUP | D26: 202 | E26: 80 | F26: 2500 | G26: 118 | H26: =G26+G26*I26 -> 139.24 | I26: 0.18
A27: =A26+1 -> 5 | B27: 4028A | C27: 360 ML PAPER CUP - DELUXE | E27: 90 | F27: 2000 | G27: 165 | H27: =G27+G27*I27 -> 194.7 | I27: 0.18
A28: =A27+1 -> 6 | B28: 4032 | C28: 4032 480ml OE S/W Paper Cup SB [Plain] * 1000pcs | E28: 90 | F28: 1000 | G28: 177 | H28: =G28+G28*I28 -> 208.86 | I28: 0.18
A29: =A28+1 -> 7 | B29: 4037 | C29: 650 ML PAPER CUP SB | E29: 90 | F29: 500 | G29: 215 | H29: =G29+G29*I29 -> 253.7 | I29: 0.18
A30: =A29+1 -> 8 | B30: 4039 | C30: 720 ML PAPER CUP | E30: 90 | F30: 500 | G30: 295 | H30: =G30+G30*I30 -> 348.1 | I30: 0.18
A31: Common Printed Cups (HSN CODE 48236900)
A32: 1 | B32: 4003 | C32: 100 ML PAPER CUP | D32: 182 | E32: 62 | F32: 6000 | G32: 0.44 | H32: =G32+G32*I32 -> 0.5192 | I32: 0.18
A33: =A32+1 -> 2 | B33: 4006 | C33: 130 ML PAPER CUP | D33: 182 | E33: 65 | F33: 6000 | G33: 0.49 | H33: =G33+G33*I33 -> 0.5782 | I33: 0.18
A34: =A33+1 -> 3 | B34: 4009 | C34: 150 ML PAPER CUP | D34: 182 | E34: 70 | F34: 5000 | G34: 0.59 | H34: =G34+G34*I34 -> 0.6962 | I34: 0.18
A35: =A34+1 -> 4 | B35: 4013 | C35: 200 ML PAPER CUP | D35: 182 | E35: 73 | F35: 4000 | G35: 0.69 | H35: =G35+G35*I35 -> 0.8142 | I35: 0.18
A36: =A35+1 -> 5 | B36: 4017 | C36: 250 ML PAPER CUP | D36: 182 | E36: 73 | F36: 4000 | G36: 0.9 | H36: =G36+G36*I36 -> 1.062 | I36: 0.18
A37: =A36+1 -> 6 | B37: 4018 | C37: 250 ML PAPER CUP | D37: 182 | E37: 80 | F37: 2500 | G37: 0.98 | H37: =G37+G37*I37 -> 1.1564 | I37: 0.18
A38: =A37+1 -> 7 | B38: 4022 | C38: 300 ML PAPER CUP | D38: 202 | E38: 80 | F38: 2500 | G38: 1 | H38: =G38+G38*I38 -> 1.18 | I38: 0.18
A39: =A38+1 -> 8 | B39: 4023 | C39: 300 ML PAPER CUP SB | D39: 202 | E39: 90 | F39: 2500 | G39: 1.4 | H39: =G39+G39*I39 -> 1.652 | I39: 0.18
A40: =A39+1 -> 9 | B40: 4026 | C40: 330 ML PAPER CUP | D40: 202 | E40: 80 | F40: 2500 | G40: 1.18 | H40: =G40+G40*I40 -> 1.3924 | I40: 0.18
A41: =A40+1 -> 10 | B41: 4029 | C41: 360 ML PAPER CUP SB | D41: 222 | E41: 90 | F41: 2000 | G41: 1.65 | H41: =G41+G41*I41 -> 1.947 | I41: 0.18
...

Sheet Olive Products
A1: Neeyog Packaging | K1: Summary Sheet | Q1: Mamtora | R1: MM
A2: OFF:G20, Gr Floor,Sidhpura Ind.Estate,S.V.Road,Gaiwadi Rd,Near Agilus Diagnostic Center,Goregaon(W),Mum- 062 | M2: NL | N2: New Launch | Q2: Bhiwandi | R2: BW
A3: Phone : 022-28760709 Mobile 9867607003 Email:neeyog@gmail.com | M3: FM | O3: 1-2 DAY | Q3: Shop | R3: SH
A4: www.neeyog.com/www.neeyog.net/www.indiamart.com/neeyogpackaging/www.facebook.com/neeyogpack | M4: LS | N4: Limited Stock | O4: 3-4 DAYS | Q4: Vapi | R4: VP
M5: APO | N5: As per Order | O5: 15-20 DAYS | Q5: Bansi | R5: BN
A6: Wholesale Olive Classic Paper Products Price List | H6: ='Summary Sheet'!C7 -> Date 16.06.2026
A7: SINGLE WALL CUPS
A8: PRICE LIST - CLASSIC SERIES
A9: CLASSIC SINGLE WALL CUPS (HSN CODE 48236900) | K9: Primary Godown | L9: Movement
A10: SR No | C10: Code | D10: Description | E10: GSM | F10: Top Dia | G10: Box Packing | H10: Basic Price / Pcs | I10: Incl GST /Pcs | J10: GST %
D11: Single Wall Plain Cups | K11: APO | L11: FM
A12: 1 | B12: 4003C | C12: 4003C | D12: 100 ML PAPER CUP | F12: 62 | G12: 6300 | H12: 0.45 | I12: =H12+H12*J12 -> 0.531 | J12: 0.18
A13: =A12+1 -> 2 | B13: 4006C | C13: 4006C | D13: 130 ML PAPER CUP | F13: 65 | G13: 6300 | H13: 0.51 | I13: =H13+H13*J13 -> 0.6018 | J13: 0.18
A14: =A13+1 -> 3 | B14: 4008C | C14: 4008C | D14: 150 ML TALL PAPER CUP | F14: 65 | G14: 5400 | H14: 0.53 | I14: =H14+H14*J14 -> 0.6254 | J14: 0.18
A15: =A14+1 -> 4 | B15: 4009C | C15: 4009C | D15: 150 ML PAPER CUP | F15: 70 | G15: 4800 | H15: 0.53 | I15: =H15+H15*J15 -> 0.6254 | J15: 0.18
A16: =A15+1 -> 5 | B16: 4013C | C16: 4013C | D16: 200 ML PAPER CUP | F16: 73 | G16: 4800 | H16: 0.66 | I16: =H16+H16*J16 -> 0.7788 | J16: 0.18
A17: =A16+1 -> 6 | B17: 4018C | C17: 4018C | D17: 250 ML PAPER CUP | F17: 80 | G17: 4800 | H17: 0.83 | I17: =H17+H17*J17 -> 0.9794 | J17: 0.18
A18: =A17+1 -> 7 | B18: 4022C | C18: 4022C | D18: 300 ML PAPER CUP | F18: 80 | G18: 4000 | H18: 0.93 | I18: =H18+H18*J18 -> 1.0974 | J18: 0.18
A19: =A18+1 -> 8 | B19: 4026C | C19: 4026C | D19: 330 ML PAPER CUP | F19: 80 | G19: 3000 | H19: 0.98 | I19: =H19+H19*J19 -> 1.1564 | J19: 0.18
A20: =A19+1 -> 9 | B20: 4029C | C20: 4029C | D20: 360 ML PAPER CUP SB | F20: 90 | G20: 2000 | H20: 1.35 | I20: =H20+H20*J20 -> 1.593 | J20: 0.18
A21: =A20+1 -> 10 | B21: 4032C | C21: 4032C | D21: 480 ML PAPER CUP SB | F21: 90 | G21: 1000 | H21: 1.6 | I21: =H21+H21*J21 -> 1.888 | J21: 0.18
A22: CLASSIC ICE CREAM CUP (HSN CODE 48236900)
A23: 1 | C23: 4051CPL | D23: 50 ML SAUCE CUP - PLAIN | F23: 62 | G23: 5000 | H23: 0.44 | I23: =H23+H23*J23 -> 0.5192 | J23: 0.18
A24: 2 | C24: 4055CPL | D24: 90 ML ICE CREAM CUP - PLAIN | F24: 64 | G24: 4000 | H24: 0.51 | I24: =H24+H24*J24 -> 0.6018 | J24: 0.18
A25: SR No | C25: Code | D25: Description | F25: Top Dia | G25: Box Packing | H25: Basic Price / Pcs | I25: Incl GST /Pcs | J25: GST %
A26: CLASSIC RIPPLE CUPS (HSN CODE 48236900)
A27: 1 | C27: 4003RHKC | D27: 100 ML RIPPLE PAPER CUP | E27: 362 | F27: 62 | G27: 3000 | H27: 0.91 | I27: =H27+H27*J27 -> 1.0738 | J27: 0.18
A28: =A27+1 -> 2 | C28: 4006RHKC | D28: 130 ML RIPPLE PAPER CUP | E28: 362 | F28: 62 | G28: 3000 | H28: 0.93 | I28: =H28+H28*J28 -> 1.0974 | J28: 0.18
A29: =A28+1 -> 3 | C29: 4008RHKC | D29: 150 ML TALL RIPPLE CUP | F29: 65 | G29: 3000 | H29: 0.99 | I29: =H29+H29*J29 -> 1.1682 | J29: 0.18
A30: =A29+1 -> 4 | C30: 4009RHKC | D30: 150 ML PAPER CUP | E30: 362 | F30: 70 | G30: 3000 | H30: 0.99 | I30: =H30+H30*J30 -> 1.1682 | J30: 0.18
A31: =A30+1 -> 5 | C31: 4013RHKC | D31: 4013R(H)KC 200ML OE Ripple Glass Brown ( 73D) * 2000 | E31: 362 | F31: 73 | G31: 2000 | H31: 1.23 | I31: =H31+H31*J31 -> 1.4514 | J31: 0.18
A32: =A31+1 -> 6 | C32: 4018RHKC | D32: 250 ML RIPPLE PAPER CUP | F32: 80 | G32: 2000 | H32: 1.63 | I32: =H32+H32*J32 -> 1.9234 | J32: 0.18
A33: CLASSIC PLATS & BOWL -GST 18 % EXTRA
A34: 1 | B34: 4501CPL | C34: 4501CPL | D34: 4"X4" PAPER DONA - PLAIN | G34: 6000 | H34: 0.57 | I34: =H34+H34*J34 -> 0.6726 | J34: 0.18
A35: 2 | B35: 4502CPL | C35: 4502CPL | D35: 5"X5" PAPER PLATE - PLAIN | G35: 4000 | H35: 0.89 | I35: =H35+H35*J35 -> 1.0502 | J35: 0.18
A36: 3 | B36: 4506CPL | C36: 4506CPL | D36: 150 ML PAPER BOWL - PLAIN | G36: 6000 | H36: 0.57 | I36: =H36+H36*J36 -> 0.6726 | J36: 0.18
A37: 4 | B37: 4507CPL | C37: 4507CPL | D37: 200 ML PAPER BOWL - PLAIN | G37: 4000 | H37: 0.77 | I37: =H37+H37*J37 -> 0.9086 | J37: 0.18
A38: 5 | B38: 4515CPL | C38: 4515CPL | D38: 6" PAPER PLATE - PLAIN | G38: 4000 | H38: 0.89 | I38: =H38+H38*J38 -> 1.0502 | J38: 0.18
A39: 6 | B39: 4518CPL | C39: 4518CPL | D39: 7" PAPER PLATE - PLAIN | G39: 3000 | H39: 1.25 | I39: =H39+H39*J39 -> 1.475 | J39: 0.18
A40: CLASSIC PAPER STRAW | F40: Sleeves | G40: Box Packing | H40: Basic Price / Pcs | I40: Incl GST /Pcs | J40: GST %
...

Sheet PNS
A1: Neeyog Packaging | K1: Summary Sheet' | P1: Mamtora | Q1: MM
A2: OFF: 20, Gr Floor,Sidhpura Ind.Estate,S.V.Road,Gaiwadi Rd,Near Agilus Diagnostic Center,Goregaon(W),Mum- 062 | L2: NL | M2: New Launch | P2: Bhiwandi | Q2: BW
A3: Phone : 28760709 Mobile 9867607003 Email:neeyog@gmail.com | L3: FM | N3: 1-2 DAY | P3: Shop | Q3: SH
A4: www.neeyog.com/www.indiamart.com/neeyogpackaging/www.facebook.com/neeyogpack | L4: LS | M4: Limited Stock | N4: 3-4 DAYS | P4: Vapi | Q4: VP
L5: APO | M5: As per Order | N5: 15-20 DAYS | P5: Bansi | Q5: BN
A6: Paknserve Paper Product Price List | G6: ='Summary Sheet'!C7 -> Date 16.06.2026
A8: Sr. No. | B8: Code | C8: HSN Code | D8: Photos | E8: Paper PRODUCTS | F8: Rate Excl GST | G8: Rate Incl GST | H8: Per | I8: Packing | J8: Gst | K8: Primary Godown | L8: Movement
E9: PNS Economy
A10: 1 | B10: PNS01 | C10: 48191010 | E10: Popcorn Pocket Small | F10: 1.35 | G10: =F10+F10*J10 -> 1.4175 | H10: Pcs | J10: 0.05
A11: =A10+1 -> 2 | B11: PNS02 | C11: 48191010 | E11: PNS 20 OZ Popcorn Box * 2000 Pcs | F11: 2.5 | G11: =F11+F11*J11 -> 2.625 | H11: Pcs | I11: 2000 | J11: 0.05
A12: =A11+1 -> 3 | B12: PNS03 | C12: 48191010 | E12: PNS 32 OZ SQ Popcorn Box * 400Pcs | F12: 3.6 | G12: =F12+F12*J12 -> 3.78 | H12: Pcs | I12: 400 | J12: 0.05
A13: =A12+1 -> 4 | B13: PNS04 | C13: 48191010 | E13: PNS 64 OZ SQ Popcorn Box * 400Pcs | F13: 4.8 | G13: =F13+F13*J13 -> 5.04 | H13: Pcs | I13: 400 | J13: 0.05
A14: =A13+1 -> 5 | B14: PNS05 | C14: 48191010 | E14: PNS Waffle Cone | F14: 1.6 | G14: =F14+F14*J14 -> 1.68 | H14: Pcs | I14: 5000 | J14: 0.05
A15: =A14+1 -> 6 | B15: PNS06 | C15: 48236900 | E15: PNS ITC WAFFLE TRAY ENJOY 9.5X2.50X1.50 (COM PRNT) | F15: 3.2 | G15: =F15+F15*J15 -> 3.776 | H15: Pcs | I15: 2000 | J15: 0.18
A16: =A15+1 -> 7 | B16: PNS07 | C16: 48191010 | E16: PNS ITC WAFFLE BOX 9.5X2.50X1.50 (200Gsm) | F16: 3.55 | G16: =F16+F16*J16 -> 3.7275 | H16: Pcs | I16: 2000 | J16: 0.05
A17: =A16+1 -> 8 | B17: PNS08 | C17: 48191010 | E17: 1Cup Duplex Kraft Holder (PNS) * 1600pcs | F17: 2.25 | G17: =F17+F17*J17 -> 2.3625 | H17: Pcs | I17: 3000 | J17: 0.05
A18: =A17+1 -> 9 | B18: PNS09 | C18: 48191010 | E18: JP-30-1401 2Cup Kraft Duplex Holder | F18: 2.75 | G18: =F18+F18*J18 -> 2.8875 | H18: Pcs | I18: 2000 | J18: 0.05
A19: =A18+1 -> 10 | B19: PNS10 | C19: 48191010 | E19: PNS ITC WRAP ROLL BOX ENJOY RED/GREEN*3200PCS (COM PRNT) | F19: 2.2 | G19: =F19+F19*J19 -> 2.31 | H19: Pcs | I19: 3200 | J19: 0.05 | L19: 2000
A20: =A19+1 -> 11 | B20: PNS11 | C20: 48236900 | E20: PNS KRAFT WRAP ROLL BOX *1500PCS | F20: 3.62 | G20: =(F20*J20)+F20 -> 3.801 | H20: Pcs | I20: 1500 | J20: 0.05
A21: =A20+1 -> 12 | B21: PNS12 | C21: 48191010 | E21: PNS ITC PEDA BOX 45x45x30MM *6000PCS (COM PRNT) | F21: 1.8 | G21: =F21+F21*J21 -> 1.89 | H21: Pcs | I21: 3000 | J21: 0.05
A22: =A21+1 -> 13 | B22: PNS13 | C22: 48191010 | E22: Kraft Wrapp Box Small Enjoy 8"X2"X2" (With Inside Lamination) KRAFT WRAP BOX SMALL ENJOY 280G | F22: 2.7 | G22: =(F22*J22)+F22 -> 2.835 | H22: Pcs | I22: 100 | J22: 0.05 | K22: SHOP | L22: FM
A23: =A22+1 -> 14 | B23: PNS14 | C23: 48191010 | E23: Kraft Wrapp Box Large Enjoy 8"X2.5"X2.5" (With Inside Lamination) KRAFT WRAP BOX LARGE ENJOY 280G | F23: 3.25 | G23: =(F23*J23)+F23 -> 3.4125 | H23: Pcs | I23: 100 | J23: 0.05 | K23: SHOP | L23: FM
A24: =A23+1 -> 15 | B24: PNS15 | E24: Kraft Dosa box Enjoy 12"X3"X1.75" (With Inside Lamination) KRAFT DOSA BOX ENJOY 280G | F24: 3.8 | G24: =(F24*J24)+F24 -> 3.99 | H24: Pcs | I24: 100 | J24: 0.05 | K24: SHOP | L24: FM
C25: 48191010 | E25: Kraft 4*4*3 ENjoy Box (SNACK BOX) | F25: 3.4 | G25: =(F25*J25)+F25 -> 3.57 | H25: Pcs | I25: 100 | J25: 0.05
C26: 48191010 | E26: Kraft 5*5*3 ENjoy Box (BURGER BOX) | F26: 4.75 | G26: =(F26*J26)+F26 -> 4.9875 | H26: Pcs | I26: 100 | J26: 0.05
C27: 48191010 | E27: Kraft 7*5*3 ENjoy Box (SNACK BOX) | F27: 5.4 | G27: =(F27*J27)+F27 -> 5.67 | H27: Pcs | I27: 100 | J27: 0.05
C28: 48191010 | E28: Kraft 9*6*3 ENjoy Box | F28: 8 | G28: =(F28*J28)+F28 -> 8.4 | H28: Pcs | I28: 100 | J28: 0.05
A29: =A24+1 -> 16 | B29: PNS16 | C29: 48236900 | E29: PNS French Fries Plain Brown (A&M) * 3200Pcs | F29: 1.9 | G29: =(F29*J29)+F29 -> 2.242 | H29: Pcs | I29: 3200 | J29: 0.18
A30: =A29+1 -> 17 | B30: PNS17 | C30: 48191010 | E30: KRAFT 3X3X2 WINDOW 280G | F30: 2.5 | G30: =F30+F30*J30 -> 2.625 | H30: Pcs | I30: 500 | J30: 0.05 | K30: SHOP | L30: FM
A31: =A30+1 -> 18 | B31: PNS18 | C31: 48192020 | E31: PNS Window Sandwich Box [VP] *600Pcs | F31: 3.9 | G31: =(F31*J31)+F31 -> 4.095 | H31: Pcs | I31: 3200 | J31: 0.05 | K31: SHOP | L31: FM
A32: =A31+1 -> 19 | B32: PNS19 | C32: 48192020 | E32: PNS Small Burger Box (100x100x80mm) [VP]*300Pcs | F32: 4.15 | G32: =(F32*J32)+F32 -> 4.3575 | H32: Pcs | I32: 300 | J32: 0.05
A33: 20 | B33: PNS20 | C33: 48192020 | E33: PNS Big Burger Box (110x110x90mm) [VP]*200Pcs | F33: 4.7 | G33: =(F33*J33)+F33 -> 4.935 | H33: Pcs | I33: 200 | J33: 0.05
A34: 21 | B34: PNS21 | C34: 48236900 | E34: PNS 300ml Paper Tray [VP] ( 135x80x30mm) *PCS | F34: 2.45 | G34: =(F34*J34)+F34 -> 2.891 | H34: Pcs | I34: 900 | J34: 0.18
A35: =A34+1 -> 22 | B35: PNS22 | C35: 48236900 | E35: PNS 500ml Paper Tray [VP] (135x85x40mm) * PCS | F35: 2.8 | G35: =(F35*J35)+F35 -> 3.304 | H35: Pcs | I35: 900 | J35: 0.18
A36: =A35+1 -> 23 | B36: PNS23 | C36: 48236900 | E36: PNS 750ml Paper Trays (150x100x)[VP]* PCS | F36: 3.25 | G36: =(F36*J36)+F36 -> 3.835 | H36: Pcs | I36: 600 | J36: 0.18
A37: =A36+1 -> 24 | B37: PNS24 | C37: 48236900 | E37: PNS 1000ml Paper Trays (165x120x) [VP] * PCS | F37: 3.55 | G37: =(F37*J37)+F37 -> 4.189 | H37: Pcs | I37: 300 | J37: 0.18
A38: =A37+1 -> 25 | B38: PNS25 | C38: 48236900 | E38: PNS Single Waffle Box | F38: 5.35 | G38: =(F38*J38)+F38 -> 5.6175 | H38: Pcs | I38: 1200 | J38: 0.05
A39: =A38+1 -> 26 | B39: PNS26 | C39: 48236900 | E39: PNS Double Waffle Box | F39: 6.45 | G39: =(F39*J39)+F39 -> 6.7725 | H39: Pcs | I39: 900 | J39: 0.05
A40: =A39+1 -> 27 | B40: PNS27 | C40: 48236900 | E40: Quick Pack Snack Box | F40: 5.15 | G40: =(F40*J40)+F40 -> 5.4075 | H40: Pcs | I40: 900 | J40: 0.05
A41: =A40+1 -> 28 | B41: PNS28 | C41: 48236900 | E41: 4.5 " PNS Paper Boat Tray | F41: 1.15 | G41: =(F41*J41)+F41 -> 1.357 | H41: Pcs | I41: 8000 | J41: 0.18
...

Sheet JP Product
A1: Neeyog Packaging
A2: OFF:20, Gr Floor,Sidhpura Ind.Estate,S.V.Road,Gaiwadi Rd,Near Agilus Diagnostic Center,Goregaon(W),Mum- 062
A3: Phone : 022-28760709 Mobile 9867607003 Email:neeyog@gmail.com
A4: www.neeyog.com/www.indiamart.com/neeyogpackaging/www.facebook.com/neeyogpack
K5: ='Summary Sheet'!C7 -> Date 16.06.2026
A6: JP Product Price List
A8: Sr No | B8: Photos | C8: Item Name | D8: Item Code No | E8: Size in (mm) | F8: Board | G8: Basic | H8: Rate Incl Gst | I8: Box Pack | J8: MOQ Pack | K8: HSN code | L8: GST%
A9: FLAT BOXES
A10: 1 | C10: Wrap box | D10: JP-0A-8002 | E10: 203 x 50 x 45 | F10: FBB | G10: 3.4 | H10: =G10+G10*L10 -> 3.57 | I10: 1000 | J10: 3000 | K10: 48192020 | L10: 0.05
A11: 2 | C11: Wrap box Big | D11: JP-0A-8006 | E11: 203 x 65 x 65 | F11: FBB | G11: 4.85 | H11: =G11+G11*L11 -> 5.0925 | I11: 400 | J11: 2400 | K11: 48192020 | L11: 0.05
A12: 3 | C12: Unprinted Dosa Box | D12: JP-0H-8007 | E12: 305 x 76 x 45 | F12: Duplex with FGC | G12: 4.2 | H12: =G12+G12*L12 -> 4.41 | I12: 500 | J12: 1500 | K12: 48192020 | L12: 0.05
A13: 4 | C13: Unprinted Frankie | D13: JP-0A-8008 | E13: 227 x 70 x 90 | F13: FBB | G13: 2.25 | H13: =G13+G13*L13 -> 2.3625 | I13: 1200 | J13: 2400 | K13: 48192020 | L13: 0.05
A14: 5 | C14: Kraft Frankie | D14: JP-0M-8008 | E14: 227 x 70 x 90 | F14: Kraft | G14: 2.25 | H14: =G14+G14*L14 -> 2.3625 | I14: 1200 | J14: 2400 | K14: 48192020 | L14: 0.05
A15: 6 | C15: Frankie Generic Printed | D15: JP-0A-8008 | E15: 227 x 70 x 90 | F15: FBB | G15: 2.65 | H15: =G15+G15*L15 -> 2.7825 | I15: 1200 | J15: 2400 | K15: 48192020 | L15: 0.05
A16: 7 | C16: Waffle Pouch | D16: JP-25A-5008 | E16: 5x5x1 inches | F16: FBB | G16: 2.7 | H16: =G16+G16*L16 -> 2.835 | I16: 1500 | J16: 3000 | K16: 48192020 | L16: 0.05
A17: 8 | C17: Single Waffle Box | D17: JP-25A-5009 | E17: 11.5 x 5.5 x 11.2 | F17: FBB | G17: 5.6 | H17: =G17+G17*L17 -> 5.88 | I17: 500 | J17: 1500 | K17: 48192020 | L17: 0.05
A18: BURGER BOXES
A19: 9 | C19: Burger Box | D19: JP-1A-1001 | E19: 110 x 110 x 55 | F19: FBB | G19: 5.25 | H19: =G19+G19*L19 -> 5.5125 | I19: 300 | J19: 600 | K19: 48192020 | L19: 0.05
A20: 10 | C20: Unprinted Burger Box | D20: JP-1A-1001 | E20: 110 x 110 x 55 | F20: FBB | G20: 4.8 | H20: =G20+G20*L20 -> 5.04 | I20: 300 | J20: 600 | K20: 48192020 | L20: 0.05
A21: SANDWICH BOXES
A22: 11 | C22: Sandwich Box | D22: JP-10A-6001 | E22: 123(l)x123(B)x74(W) | F22: FBB | G22: 5 | H22: =G22+G22*L22 -> 5.25 | I22: 400 | J22: 1600 | K22: 48192020 | L22: 0.05
A23: 12 | C23: Unprinted Sandwich Box | D23: JP-10A-6001 | E23: 123(l)x123(B)x74(W) | F23: FBB | G23: 4.65 | H23: =G23+G23*L23 -> 4.8825 | I23: 400 | J23: 1600 | K23: 48192020 | L23: 0.05
A24: 13 | C24: Single Sandwich Box | D24: JP-10A-6004 | E24: 167 x 85 x 55 | F24: FBB | G24: 4.8 | H24: =G24+G24*L24 -> 5.04 | I24: 500 | J24: 2000 | K24: 48192020 | L24: 0.05
A25: 14 | C25: Indian Grill Sandwich | D25: JP-11A-6002 | E25: 130 x 110 x 50 | F25: FBB | G25: 5.8 | H25: =G25+G25*L25 -> 6.09 | I25: 600 | J25: 1200 | K25: 48192020 | L25: 0.05
A26: POPCORN BOXES
A27: 15 | C27: Popcorn 32 oz | D27: JP-8A-7005 | E27: 100 x 100 x 117 | F27: FBB | G27: 5.35 | H27: =G27+G27*L27 -> 6.313 | I27: 400 | J27: 800 | K27: 48236900 | L27: 0.18
A28: 16 | C28: Popcorn 64 oz | D28: JP-8A-7004 | E28: 120 x 120 x 190 | F28: FBB | G28: 7.2 | H28: =G28+G28*L28 -> 8.496 | I28: 500 | J28: 1000 | K28: 48236900 | L28: 0.18
A29: CUP HOLDERS
A30: 17 | C30: 2 Cup Holder | D30: JP-30-1401 | E30: 180 x 90 x 50 | F30: Duplex | G30: 2.65 | H30: =G30+G30*L30 -> 2.7825 | I30: 700 | J30: 1400 | K30: 48192020 | L30: 0.05
A31: 18 | C31: Single cup Holder | D31: JP-30-1415 | E31: 90 x 90 x 50 | F31: Duplex | G31: 2.35 | H31: =G31+G31*L31 -> 2.4675 | I31: 1000 | J31: 2000 | K31: 48192020 | L31: 0.05
A32: 19 | C32: 4 cup Holder | D32: JP-30-1402 | E32: 180 x 180 x 50 | F32: Duplex | G32: 6 | H32: =G32+G32*L32 -> 6.3 | I32: 500 | J32: 1000 | K32: 48192020 | L32: 0.05
A33: MEAL BOXES
A34: 20 | C34: 500 ml Meal box | D34: JP-7A-4003 | E34: 95 x 85 x 90 | F34: FBB | G34: 5.9 | H34: =G34+G34*L34 -> 6.195 | I34: 300 | J34: 600 | K34: 48192020 | L34: 0.05
A35: 21 | C35: 700 ml Meal box | D35: JP-7A-4004 | E35: 130 x 105 x 60 | F35: FBB | G35: 6.15 | H35: =G35+G35*L35 -> 6.4575 | I35: 300 | J35: 600 | K35: 48192020 | L35: 0.05
A36: 22 | C36: Single Serving Mealbox | D36: JP-29-1305 | E36: 170(l)x180(b)x125(w) | F36: Whiteback | G36: 13.1 | H36: =G36+G36*L36 -> 13.755 | I36: 250 | J36: 250 | K36: 48192020 | L36: 0.05
A37: FRIES SCOOP
A38: 23 | C38: Fries Scoop (small) | D38: JP-9A-1201 | E38: 80 x 90 | F38: FBB | G38: 2.35 | H38: =G38+G38*L38 -> 2.4675 | I38: 600 | J38: 2400 | K38: 48192020 | L38: 0.05
A39: 24 | C39: Fries Cone with sauce pocket | D39: JP-9A-1207 | E39: 280x200x165 | F39: FBB | G39: 3.6 | H39: =G39+G39*L39 -> 3.78 | I39: 1000 | J39: 2000 | K39: 48192020 | L39: 0.05
A40: SNACK BOXES
A41: Sr No | B41: Photos | C41: Item Name | D41: Item Code No | E41: Size in (mm) | F41: Board | G41: Basic | H41: Rate Incl Gst | I41: Box Pack | J41: MOQ Pack | K41: HSN code | L41: GST%
...

Sheet PS
A1: Neeyog Packaging | I1: Summary Sheet' | P1: Mamtora | Q1: MM
A2: OFF: 20, Gr Floor,Sidhpura Ind.Estate,S.V.Road,Gaiwadi Rd,Near Agilus Diagnostic Center,Goregaon(W),Mum- 062 | L2: NL | M2: New Launch | P2: Bhiwandi | Q2: BW
A3: Phone : 28760709 Mobile 9867607003 Email:neeyog@gmail.com | L3: FM | N3: 1-2 DAY | P3: Shop | Q3: SH
A4: www.neeyog.com/www.indiamart.com/neeyogpackaging/www.facebook.com/neeyogpack | L4: LS | M4: Limited Stock | N4: 3-4 DAYS | P4: Vapi | Q4: VP
L5: APO | M5: As per Order | N5: 15-20 DAYS | P5: Bansi | Q5: BN
A6: Wholesale PS items Products Price List | E6: ='Summary Sheet'!C7 -> Date 16.06.2026
A8: Sr. No. | B8: HSN CODE | C8: PS PRODUCTS (HSN Code - 39249090) | D8: Rate Excl GST | E8: Rate Incl GST | F8: Per | G8: Packing | H8: GST | I8: Primary Godown | J8: Movement
C9: NP Products
A10: 1 | B10: 39249090 | C10: NP PS 1 SQ Biq 250ml Cup (N25) | D10: 5.15 | E10: =D10*1.18 -> 6.077 | F10: Pcs | G10: 1200 | H10: 0.18 | I10: BN | J10: FM
A11: =A10+1 -> 2 | B11: 39249090 | C11: NP PS 2 Big Triangle Cont 175ml | D11: 4.5 | E11: =D11*1.18 -> 5.31 | F11: Pcs | G11: 1200 | H11: 0.18 | I11: BN | J11: FM
A12: =A11+1 -> 3 | B12: 39249090 | C12: NP PS 3 Triangle Small Cup 60ml | D12: 1.85 | E12: =D12*1.18 -> 2.183 | F12: Pcs | G12: 3900 | H12: 0.18 | I12: BN | J12: FM
A13: =A12+1 -> 4 | B13: 39249090 | C13: NP PS 4 SQ Small Cup 60ml | D13: 1.85 | E13: =D13*1.18 -> 2.183 | F13: Pcs | G13: 3000 | H13: 0.18 | I13: BN | J13: FM
A14: =A13+1 -> 5 | B14: 39249090 | C14: NP PS 5 Hexa Shot Glass 60ml | D14: 1.85 | E14: =D14*1.18 -> 2.183 | F14: Pcs | G14: 3000 | H14: 0.18 | I14: BN | J14: FM
A15: =A14+1 -> 6 | B15: 39249090 | C15: NP PS 6 Solo Shot Glass | D15: 1.85 | E15: =D15*1.18 -> 2.183 | F15: Pcs | G15: 2000 | H15: 0.18 | I15: BN | J15: FM
A16: =A15+1 -> 7 | B16: 39249090 | C16: NP PS 7 SQ Cup 80 ml | D16: 2.65 | E16: =D16*1.18 -> 3.127 | F16: Pcs | G16: 2000 | H16: 0.18 | I16: BN | J16: LS
A17: =A16+1 -> 8 | B17: 39249090 | C17: NP PS 8 SQ 120ml Cup | D17: 4.25 | E17: =D17*1.18 -> 5.015 | F17: Pcs | G17: 1200 | H17: 0.18 | I17: BW | J17: FM
A18: =A17+1 -> 9 | B18: 39249090 | C18: NP PS 9 - 4 inch Boat Tray (Black/Clear) | D18: 2.15 | E18: =D18*1.18 -> 2.537 | F18: Pcs | G18: 3000 | H18: 0.18 | I18: BW | J18: FM
A19: =A18+1 -> 10 | B19: 39249090 | C19: NP PS 10 Flower Wati 60ml | D19: 2.1 | E19: =D19*1.18 -> 2.478 | F19: Pcs | G19: 3000 | H19: 0.18 | I19: BW | J19: FM
A20: =A19+1 -> 11 | B20: 39249090 | C20: NP PS 11 - 6" Flower Plate (Black / Trans) | D20: 4.3 | E20: =D20*1.18 -> 5.074 | F20: Pcs | G20: 1000 | H20: 0.18 | I20: BW | J20: LS
A21: =A20+1 -> 12 | B21: 39249090 | C21: NP PS 12 Chamcham Wati (Old NP PS 22) | D21: 1.9 | E21: =D21*1.18 -> 2.242 | F21: Pcs | G21: 6000 | H21: 0.18 | J21: APO
A22: =A21+1 -> 13 | B22: 39249090 | C22: NP PS 13 125ml Matka Cont [Trans] | D22: 3.1 | E22: =D22*1.18 -> 3.658 | F22: Pcs | G22: 1200 | H22: 0.18 | I22: BW | J22: FM
A23: =A22+1 -> 14 | B23: 39249090 | C23: NP PS 14 Square Cont 100ml [Trans] | D23: 3.35 | E23: =D23*1.18 -> 3.953 | F23: Pcs | G23: 1200 | H23: 0.18 | J23: APO
A24: =A23+1 -> 15 | B24: 39249090 | C24: NP PS 15 Rect Mousse Cont 120ml | D24: 3.65 | E24: =D24*1.18 -> 4.307 | F24: Pcs | G24: 1200 | H24: 0.18 | I24: BW | J24: FM
A25: =A24+1 -> 16 | B25: 39249090 | C25: NP PS 16 Tequila Shot Cont 30ml | D25: 1.3 | E25: =D25*1.18 -> 1.534 | F25: Pcs | G25: 1600 | H25: 0.18 | J25: APO
A26: =A25+1 -> 17 | B26: 39249090 | C26: NP PS 17 Ice Cream Bowl [Blk/Trans] | D26: 3.1 | E26: =D26*1.18 -> 3.658 | F26: Pcs | G26: 3000 | H26: 0.18 | J26: APO
A27: =A26+1 -> 18 | B27: 39249090 | C27: NP PS 18 SQ Jelly Cont 60ml | D27: 1.25 | E27: =D27*1.18 -> 1.475 | F27: Pcs | G27: 5000 | H27: 0.18 | J27: APO
A28: =A27+1 -> 19 | B28: 39249090 | C28: NP PS 19 3" RD Starter Plate (Black/Trans) * 6000pcs | D28: 1.25 | E28: =D28*1.18 -> 1.475 | F28: Pcs | G28: 6000 | H28: 0.18 | J28: APO
A29: =A28+1 -> 20 | B29: 39249090 | C29: NP-PS-20 100ml Cup (Clear) | D29: 2.5 | E29: =D29*1.18 -> 2.95 | F29: Pcs | G29: 1500 | H29: 0.18 | I29: BW | J29: FM
A30: =A29+1 -> 21 | B30: 39249090 | C30: NP PS 21 Rect Pastry Tray (Blk) | D30: 2.45 | E30: =D30*1.18 -> 2.891 | F30: Pcs | G30: 2500 | H30: 0.18 | I30: BW | J30: LS
A31: =A30+1 -> 22 | B31: 39249090 | C31: NP PP 22 SQ 3x3 Tray (Blk) | D31: 2.7 | E31: =D31*1.18 -> 3.186 | F31: Pcs | G31: 2000 | H31: 0.18 | I31: BW | J31: LS
A32: =A31+1 -> 23 | B32: 39249090 | C32: NP PS 23 Pan Dish (Trans) | D32: 1.5 | E32: =D32*1.18 -> 1.77 | F32: Pcs | G32: 5000 | H32: 0.18 | J32: APO
A33: =A32+1 -> 24 | B33: 39249090 | C33: NP PS 24 Oval Dish | D33: 1.5 | E33: =D33*1.18 -> 1.77 | F33: Pcs | G33: 5000 | H33: 0.18 | J33: APO
A34: =A33+1 -> 25 | B34: 39249090 | C34: NP PS 25 4Cavity Mithai Box 125X125MM X 40MM | D34: 31.5 | E34: =D34*1.18 -> 37.17 | F34: Pcs | G34: 150 | H34: 0.18 | J34: APO
A35: =A34+1 -> 26 | B35: 39249090 | C35: NP PS 26 RD Jelly Cont 60ml [Trans] | D35: 1.25 | E35: =D35*1.18 -> 1.475 | F35: Pcs | G35: 1400 | H35: 0.18 | J35: APO
A36: =A35+1 -> 27 | B36: 39249090 | C36: NP PS 27 Cham Cham Tray RT Cont [Trans] (VE) | D36: 2 | E36: =D36*1.18 -> 2.36 | F36: Pcs | G36: 2600 | H36: 0.18 | J36: APO
A37: =A36+1 -> 28 | B37: 39249090 | C37: NP PS 28 150ml RD Glass Cont [Trans] | D37: 4.2 | E37: =D37*1.18 -> 4.956 | F37: Pcs | G37: 1400 | H37: 0.18 | J37: APO
A38: =A37+1 -> 29 | B38: 39249090 | C38: NP PS 29 200ml SQ Glass Cont [Trans] | D38: 4.8 | E38: =D38*1.18 -> 5.664 | F38: Pcs | G38: 1200 | H38: 0.18 | J38: APO
A39: =A38+1 -> 30 | C39: NP PS 30 Wine Glass 130ml | D39: 3.2 | E39: Upcoming | H39: 0.18
A40: =A39+1 -> 31 | C40: NP PS 31 (GT) Ice Cream Bowl (120ml) | D40: 3.35 | E40: =D40*1.18 -> 3.953 | F40: Pcs | G40: 1200 | H40: 0.18
A41: =A40+1 -> 32 | C41: NP PS 32 4 Cavity Sweet Box 125x125x30MM (WL) * 280Pcs | D41: 25 | E41: =D41*1.18 -> 29.5 | F41: Pcs | G41: 280 | H41: 0.18
...

Sheet SOS Bag & Sheet
A1: Neeyog Packaging | J1: Summary Sheet'!A1 | Q1: Mamtora | R1: MM
A2: OFF:20, Gr Floor,Sidhpura Ind.Estate,S.V.Road,Gaiwadi Rd,Near Agilus Diagnostic Center,Goregaon(W),Mum- 062 | M2: NL | N2: New Launch | Q2: Bhiwandi | R2: BW
A3: Phone : 022-28760709 Mobile 9867607003 Email:neeyog@gmail.com | M3: FM | O3: 1-2 DAY | Q3: Shop | R3: SH
A4: www.neeyog.com/www.neeyog.net/www.indiamart.com/neeyogpackaging/www.facebook.com/neeyogpack | M4: LS | N4: Limited Stock | O4: 3-4 DAYS | Q4: Vapi | R4: VP
M5: APO | N5: As per Order | O5: 15-20 DAYS | Q5: Bansi | R5: BN
A6: Paknserve Grocery Bags & Pouch / Ecowrapp Cut Sheet Price List | G6: Date: | H6: ='Summary Sheet'!C7 -> Date 16.06.2026
C8: V bottom MF Kraft bag 60GSm 24Bf (WxGxH) | D8: Rate/Kg | E8: Rate/Incl | F8: Pc/Kg | G8: Rate/PC | H8: Packing | I8: Gst% | J8: Primary Godown | K8: Movement | L8: Tally name
A9: 1 | B9: 48194000 | C9: 501 Kraft Bag 4x9x3 | D9: 75 | E9: =D9*I9+D9 -> 88.5 | F9: 170 | G9: =E9/F9 -> 0.52058824 | H9: 30 Kg | I9: 0.18 | J9: VP | K9: FM
A10: 2 | B10: 48194000 | C10: 502 Kraft Bag 5x11x3 | D10: 75 | E10: =D10*I10+D10 -> 88.5 | F10: 100 | G10: =E10/F10 -> 0.885 | H10: 30 Kg | I10: 0.18 | J10: VP | K10: FM
A11: 3 | B11: 48194000 | C11: 503 Kraft bag 6x11x3.5 | D11: 75 | E11: =D11*I11+D11 -> 88.5 | F11: 90 | G11: =E11/F11 -> 0.98333333 | H11: 30 Kg | I11: 0.18 | J11: VP | K11: FM
A12: 4 | B12: 48194000 | C12: 504 Kraft bag 6x13x3.5 | D12: 75 | E12: =D12*I12+D12 -> 88.5 | F12: 80 | G12: =E12/F12 -> 1.10625 | H12: 30 Kg | I12: 0.18 | J12: VP | K12: FM
A13: 5 | B13: 48194000 | C13: 505 Kraft Bag 8x15x4 | D13: 75 | E13: =D13*I13+D13 -> 88.5 | F13: 55 | G13: =E13/F13 -> 1.6090909 | H13: 30 Kg | I13: 0.18 | J13: VP | K13: FM
A14: 6 | B14: 48194000 | C14: 506Kraft bag 8x18x4 | D14: 75 | E14: =D14*I14+D14 -> 88.5 | F14: 50 | G14: =E14/F14 -> 1.77 | H14: 30 Kg | I14: 0.18 | J14: BANSI | K14: LS
C15: Brown SOS MF Kraft 80Gsm 24Bf (WxGxH) | D15: Rate/Kg | E15: Rate/Incl | F15: Pc/Kg | G15: Rate/PC | H15: Packing | I15: Gst%
A16: 1 | B16: 48194000 | C16: 6x4x12 Brown 80Gsm MF Kraft | D16: 75 | E16: =D16*I16+D16 -> 88.5 | F16: 61.507937 | G16: =E16/F16 -> 1.4388387 | H16: 30 Kg | I16: 0.18 | J16: VP | K16: FM | L16: 6.5x4x12 SOS SQ Bot Plain Brown MG Kraft (80g) * Kg
A17: 2 | B17: 48194000 | C17: 7.5x5x10 Brown 80Gsm MF Kraft | D17: 75 | E17: =D17*I17+D17 -> 88.5 | F17: 53 | G17: =E17/F17 -> 1.6698113 | H17: 30 Kg | I17: 0.18 | J17: VP | K17: FM
A18: 2 | B18: 48194000 | C18: 7x5x12 Brown 80Gsm MF Kraft | D18: 75 | E18: =D18*I18+D18 -> 88.5 | F18: 54 | G18: =E18/F18 -> 1.6388889 | H18: 30 Kg | I18: 0.18 | J18: VP | K18: FM
A19: 3 | B19: 48194000 | C19: 8.5x5x12 Brown 80Gsm MF Kraft | D19: 75 | E19: =D19*I19+D19 -> 88.5 | F19: 43 | G19: =E19/F19 -> 2.0581395 | H19: 30 Kg | I19: 0.18 | J19: VP | K19: FM
A20: 4 | B20: 48194000 | C20: 9x5x13 Brown 80Gsm MF Kraft | D20: 75 | E20: =D20*I20+D20 -> 88.5 | F20: 39 | G20: =E20/F20 -> 2.2692308 | H20: 30 Kg | I20: 0.18 | J20: VP | K20: FM
A21: 5 | B21: 48194000 | C21: 10x5x14 Brown 80Gsm MF Kraft | D21: 75 | E21: =D21*I21+D21 -> 88.5 | F21: 34 | G21: =E21/F21 -> 2.6029412 | H21: 30 Kg | I21: 0.18 | J21: VP | K21: FM | L21: 10x5x14 SOS SQ Bot Plain Brown MG Kraft (80g) * Kg
A22: 6 | B22: 48194000 | C22: 12x5x16 Brwon 80Gsm Mg Kraft | D22: 75 | E22: =D22*I22+D22 -> 88.5 | F22: 27 | G22: =E22/F22 -> 3.2777778 | H22: 30 Kg | I22: 0.18 | J22: VP | K22: FM | L22: 10x6x14 SOS SQ Bot Plain Brown MG Kraft (80g) * Kg
A23: 7 | B23: 48194000 | C23: 13x7x15 Brown 80Gsm MF Kraft | D23: 75 | E23: =D23*I23+D23 -> 88.5 | F23: 23 | G23: =E23/F23 -> 3.8478261 | H23: 30 Kg | I23: 0.18 | J23: VP | K23: FM | L23: 13x7x15 SOS SQ Bot Plain Brown MG Kraft (80g) * Kg
C24: Brown SOS MG Kraft 70Gsm 24Bf (WxGXH) | D24: Rate/Kg | E24: Rate/Incl | F24: Pc/Kg | G24: Rate/PC | H24: Packing | I24: Gst%
A25: 1 | B25: 48194000 | C25: 6x4x12 Brown 70Gsm Saffron Kraft | D25: 95 | E25: =D25*I25+D25 -> 112.1 | F25: 67 | G25: =E25/F25 -> 1.6731343 | H25: 25 Kg | I25: 0.18 | K25: APO
A26: 2 | B26: 48194000 | C26: 7x5x12 Brown 70Gsm Saffron kraft | D26: 95 | E26: =D26*I26+D26 -> 112.1 | F26: 55 | G26: =E26/F26 -> 2.0381818 | H26: 25 Kg | I26: 0.18 | K26: APO
A27: 3 | B27: 48194000 | C27: 7.5x5x10 Brown 70Gsm Saffron Kraft | D27: 95 | E27: =D27*I27+D27 -> 112.1 | F27: 61 | G27: =E27/F27 -> 1.8377049 | H27: 25 Kg | I27: 0.18 | J27: VP | K27: FM
A28: 4 | B28: 48194000 | C28: 9x5x13 Brown 70Gsm Saffron Kraft | D28: 95 | E28: =D28*I28+D28 -> 112.1 | F28: 44 | G28: =E28/F28 -> 2.5477273 | H28: 25 Kg | I28: 0.18 | J28: VP | K28: FM
C29: White SOS Mg Bleached Kraft 70Gsm 35Bf | D29: Rate/Kg | E29: Rate/Incl | F29: Pc/Kg | G29: Rate/PC | H29: Packing | I29: Gst%
A30: 1 | B30: 48194000 | C30: 6x4x12 White 70Gsm Bleached kraft | D30: 110 | E30: =D30*I30+D30 -> 129.8 | F30: 67 | G30: =E30/F30 -> 1.9373134 | H30: 2000 | I30: 0.18 | K30: APO
A31: 2 | B31: 48194000 | C31: 7.5x5x10 White 70Gsm Bleached Kraft | D31: 110 | E31: =D31*I31+D31 -> 129.8 | F31: 61 | G31: =E31/F31 -> 2.1278689 | H31: 2000 | I31: 0.18 | K31: APO
A32: 3 | B32: 48194000 | C32: 8.5x5x12 White 70Gsm Bleached Kraft | D32: 100 | E32: =D32*I32+D32 -> 118 | F32: 49 | G32: =E32/F32 -> 2.4081633 | H32: 1000 | I32: 0.18 | K32: APO
A33: 4 | B33: 48194000 | C33: 9x5x13 White 70Gsm Bleached Kraft | D33: 100 | E33: =D33*I33+D33 -> 118 | F33: 44 | G33: =E33/F33 -> 2.6818182 | H33: 1000 | I33: 0.18 | K33: APO
A34: In Bleached Kraft paper the Gsm may Vary ± 10% and Subject to availabilty of Paper
C36: EcoWrapp Paper Bag Oil proof 9Kit(OGR) | D36: Rate/Kg | E36: Rate/Incl | F36: Pc/Kg | G36: Rate/PC | H36: Packing | I36: Gst%
A37: 1 | B37: 48194000 | C37: Ecowrapp Pouch 5x8 48Gsm | D37: 160 | E37: =D37*I37+D37 -> 188.8 | F37: 330 | G37: =E37/F37 -> 0.57212121 | H37: 12 Kg | I37: 0.18 | J37: VP | K37: FM
A38: 2 | B38: 48194000 | C38: Ecowrapp Pouch 6x9 48Gsm | D38: 160 | E38: =D38*I38+D38 -> 188.8 | F38: 240 | G38: =E38/F38 -> 0.78666667 | H38: 12 Kg | I38: 0.18 | J38: VP | K38: FM
A39: 3 | B39: 48194000 | C39: Ecowrapp Pouch 8x10 48Gsm | D39: 160 | E39: =D39*I39+D39 -> 188.8 | F39: 165 | G39: =E39/F39 -> 1.1442424 | H39: 12 Kg | I39: 0.18 | J39: VP | K39: FM
A40: 4 | B40: 48194000 | C40: Ecowrapp Pouch 9x13 48Gsm | D40: 160 | E40: =D40*I40+D40 -> 188.8 | F40: 110 | G40: =E40/F40 -> 1.7163636 | H40: 12 Kg | I40: 0.18 | J40: VP | K40: LS
A41: 5 | B41: 48194000 | C41: Ecowrapp Pouch 10x11 48Gsm | D41: 160 | E41: =D41*I41+D41 -> 188.8 | F41: 100 | G41: =E41/F41 -> 1.888 | H41: 12 Kg | I41: 0.18 | J41: BN | K41: LS
A42: 6 | B42: 48194000 | C42: Ecowrapp Frankie Pouch 48Gsm (4x1.5x10 V Bot ) | D42: 0.75 | E42: =D42*I42+D42 -> 0.885 | F42: Pcs | G42: - | H42: 3000 | I42: 0.18 | J42: BN | K42: LS
...

Sheet Carry Bag With Images 
A1: Neeyog Packaging | K1: Summary Sheet' | R1: Mamtora | S1: MM
A2: OFF:G20, Gr Floor,Sidhpura Ind.Estate,S.V.Road,Gaiwadi Rd,Near Agilus Diagnostic Center,Goregaon(W),Mum- 062 | N2: NL | O2: New Launch | R2: Bhiwandi | S2: BW
A3: Phone : 022-28760709 Mobile 9867607003 Email:neeyog@gmail.com | N3: FM | P3: 1-2 DAY | R3: Shop | S3: SH
A4: www.neeyog.com/www.neeyog.net/www.indiamart.com/neeyogpackaging/www.facebook.com/neeyogpack | N4: LS | O4: Limited Stock | P4: 3-4 DAYS | R4: Vapi | S4: VP
N5: APO | O5: As per Order | P5: 15-20 DAYS | R5: Bansi | S5: BN
A6: Paknserve Paper Bags Price List (Regular) | J6: ='Summary Sheet'!C7 -> Date 16.06.2026
A8: Sr. No. | B8: HSN Code | C8: Description | D8: Excl. Gst Rate | E8: Incl. Gst Rate | F8: Packing | G8: Unit | H8: Case/Pack | I8: Gst Extra | K8: Primary Godown | L8: Movement
C9: Paper Carry Bag (L x W x H) | D9: Plain
A10: 1 | B10: 48194000 | C10: 7.5x5x10 Kraft Carry bag 80Gsm | D10: 3.5 | E10: =D10+D10*I10 -> 4.13 | F10: 50Pc | G10: Pcs | H10: 1000 | I10: 0.18 | XFD10: =SUM(A10:XFC10) -> 48195009
A11: 2 | B11: 48194000 | C11: 9x6x8.5 Kraft Carry Bag 80Gsm | D11: 3.55 | E11: =D11+D11*I11 -> 4.189 | F11: 50Pc | G11: Pcs | H11: 500 | I11: 0.18 | XFD11: =SUM(A11:XFC11) -> 48194510
A12: 3 | B12: 48194000 | C12: 11x6x11 Kraft Carry Bag 80Gsm | D12: 4.3 | E12: =D12+D12*I12 -> 5.074 | F12: 50Pc | G12: Pcs | H12: 500 | I12: 0.18 | XFD12: =SUM(A12:XFC12) -> 48194513
A13: 4 | B13: 48194000 | C13: 11x7x10 Kraft Carry Bag 80Gsm | D13: 4.65 | E13: =D13+D13*I13 -> 5.487 | F13: 50Pc | G13: Pcs | H13: 500 | I13: 0.18 | XFD13: =SUM(A13:XFC13) -> 48194514
A14: Cake/Pizza Bags | D14: Excl. Gst Rate | E14: Incl. Gst Rate | F14: Packing | G14: Unit | H14: Case/Pack | I14: Gst Extra
A15: 1 | B15: 48194000 | C15: Paper Bag 9 x 9 x 9x 120Gsm | D15: 5.85 | E15: =D15+D15*I15 -> 6.903 | F15: 50Pc | G15: Pcs | H15: 300 | I15: 0.18
A16: 2 | B16: 48194000 | C16: Paper Bag 11 x 11.5 x 9 x 120Gsm | D16: 6.5 | E16: =D16+D16*I16 -> 7.67 | F16: 50Pc | G16: Pcs | H16: 300 | I16: 0.18
A17: =A16+1 -> 3 | B17: 48194000 | C17: Paper Bag 13 x 10 x 13 120Gsm | D17: 7.3 | E17: =D17+D17*I17 -> 8.614 | F17: 50Pc | G17: Pcs | H17: 300 | I17: 0.18
A18: =A17+1 -> 4 | B18: 48194000 | C18: 8x4x10 DP Paper Carry Bag | D18: 3.8 | E18: =D18+D18*I18 -> 4.484 | F18: 50Pc | G18: Pcs | H18: 700 | I18: 0.18
A19: =A18+1 -> 5 | B19: 48194000 | C19: 8x4x12 DP Paper Carry Bag | D19: 4 | E19: =D19+D19*I19 -> 4.72 | F19: 50Pc | G19: Pcs | H19: 700 | I19: 0.18
A20: =A19+1 -> 6 | B20: 48194000 | C20: 9x5x12 DP Paper Carry Bag | D20: 4.4 | E20: =D20+D20*I20 -> 5.192 | F20: 50Pc | G20: Pcs | H20: 700 | I20: 0.18
A21: =A20+1 -> 7 | B21: 48194000 | C21: 10x4x14 DP Paper Carry Bag | D21: 4.6 | E21: =D21+D21*I21 -> 5.428 | F21: 50Pc | G21: Pcs | H21: 600 | I21: 0.18
A22: =A21+1 -> 8 | B22: 48194000 | C22: 12x5x16 DP Paper Carry Bag | D22: 4.8 | E22: =D22+D22*I22 -> 5.664 | F22: 50Pc | G22: Pcs | H22: 600 | I22: 0.18
A23: ✨ New Arrival 2025 | Exclusive Diwali, Sweets & Gift Bags Collection 🎁
A24: Sr. No. | B24: HSN Code | C24: Description | D24: Excl. Gst Rate | E24: Incl. Gst Rate | F24: Packing | G24: Unit | H24: Case/Pack | I24: Gst Extra | J24: Reference Photos
A25: Paper Carry Bag (L x W x H)
A26: 1 | B26: 48194000 | C26: 6x4x8 Gift Carry Bag 1 [Design 6] 110gsm *500Pcs | D26: 4.75 | E26: =D26+D26*I26 -> 5.605 | F26: 10 | G26: Pcs | H26: 500 | I26: 0.18
A27: =A26+1 -> 2 | B27: 48194000 | C27: 6x4x8 Gift Carry Bag 1 [Design 4] 110gsm *500Pcs | D27: 4.75 | E27: =D27+D27*I27 -> 5.605 | F27: 10 | G27: Pcs | H27: 500 | I27: 0.18 | K27: ?
A28: =A27+1 -> 3 | B28: 48194000 | C28: 7.5x5x9 Gift Carry Bag 2 [Design 5] 110gsm *500Pcs | D28: 5.2 | E28: =D28+D28*I28 -> 6.136 | F28: 10 | G28: Pcs | H28: 500 | I28: 0.18
A29: =A28+1 -> 4 | B29: 48194000 | C29: 9x7x9 Gift Carry Bag 3 [Design 3] 110gsm *500Pcs | D29: 6 | E29: =D29+D29*I29 -> 7.08 | F29: 10 | G29: Pcs | H29: 500 | I29: 0.18
A30: =A29+1 -> 5 | B30: 48194000 | C30: 10x4x14 Gift Carry Bag 4 [Design 1] 110gsm *500Pcs | D30: 8 | E30: =D30+D30*I30 -> 9.44 | F30: 10 | G30: Pcs | H30: 500 | I30: 0.18
A31: =A30+1 -> 6 | B31: 48194000 | C31: 10x4x14 Gift Carry Bag 4 [Design 2] 110gsm *500Pcs | D31: 8 | E31: =D31+D31*I31 -> 9.44 | F31: 10 | G31: Pcs | H31: 500 | I31: 0.18
A32: =A31+1 -> 7 | B32: 48194000 | C32: 13x7x10 Gift Carry Bag 5 [Design 7] 110gsm *500Pcs | D32: 7 | E32: =D32+D32*I32 -> 8.26 | F32: 10 | G32: Pcs | H32: 500 | I32: 0.18
A33: Paper Bag with Foiling Print
A34: 1 | B34: 48194000 | C34: 5x3x7 Paper Bag with Foiling Print | D34: 14 | E34: =D34+D34*I34 -> 16.52 | F34: 10 | G34: Pcs | H34: 800 | I34: 0.18
A35: =A34+1 -> 2 | B35: 48194000 | C35: 6x3x8 Paper Bag with Foiling Print | D35: 14 | E35: =D35+D35*I35 -> 16.52 | F35: 10 | G35: Pcs | H35: 800 | I35: 0.18
A36: =A35+1 -> 3 | B36: 48194000 | C36: 8x3.5x8 Paper Bag with Foiling Print | D36: 15 | E36: =D36+D36*I36 -> 17.7 | F36: 10 | G36: Pcs | H36: 500 | I36: 0.18
A37: =A36+1 -> 4 | B37: 48194000 | C37: 8x3.5x10 Paper Bag with Foiling Print | D37: 17 | E37: =D37+D37*I37 -> 20.06 | F37: 10 | G37: Pcs | H37: 500 | I37: 0.18
A38: =A37+1 -> 5 | B38: 48194000 | C38: 10x4x12 Paper Bag with Foiling Print | D38: 20 | E38: =D38+D38*I38 -> 23.6 | F38: 10 | G38: Pcs | H38: 500 | I38: 0.18
A39: =A38+1 -> 6 | B39: 48194000 | C39: 10x4x15 Paper Bag with Foiling Print | D39: 24 | E39: =D39+D39*I39 -> 28.32 | F39: 10 | G39: Pcs | H39: 500 | I39: 0.18
A40: =A39+1 -> 7 | B40: 48194000 | C40: 12x4x16 Paper Bag with Foiling Print | D40: 26 | E40: =D40+D40*I40 -> 30.68 | F40: 10 | G40: Pcs | H40: 500 | I40: 0.18
